Workbook
Name UPDATE: 'Data Sheet'!$E$1

Sheet Profit & Loss
A1: ='Data Sheet'!B1 -> OIL & NATURAL GAS CORPN LTD | H1: =UPDATE | M1: SCREENER.IN
A3: Narration | B3: ='Data Sheet'!B16 -> 42094 | C3: ='Data Sheet'!C16 -> 42460 | D3: ='Data Sheet'!D16 -> 42825 | E3: ='Data Sheet'!E16 -> 43190 | F3: ='Data Sheet'!F16 -> 43555 | G3: ='Data Sheet'!G16 -> 43921 | H3: ='Data Sheet'!H16 -> 44286 | I3: ='Data Sheet'!I16 -> 44651 | ... K3: ='Data Sheet'!K16 -> 45382 | L3: Trailing | M3: Best Case | N3: Worst Case
A4: Sales | B4: ='Data Sheet'!B17 -> 160922.64 | C4: ='Data Sheet'!C17 -> 124035.71 | D4: ='Data Sheet'!D17 -> 282506.11 | E4: ='Data Sheet'!E17 -> 322705.76 | F4: ='Data Sheet'!F17 -> 421623.93 | G4: ='Data Sheet'!G17 -> 396727.91 | H4: ='Data Sheet'!H17 -> 303848.91 | I4: ='Data Sheet'!I17 -> 491246.24 | ... K4: ='Data Sheet'!K17 -> 591396.26 | L4: =SUM(Quarters!H4:K4) -> 659221.21 | M4: =$K4+M23*K4 -> 738389.54 | N4: =$K4+N23*L4 -> 637552.93
A5: Expenses | B5: =SUM('Data Sheet'!B18,'Data Sheet'!B20:B24, -1*'Data Sheet'!B19) -> 118610.32 | C5: =SUM('Data Sheet'!C18,'Data Sheet'!C20:C24, -1*'Data Sheet'!C19) -> 84901.08 | D5: =SUM('Data Sheet'!D18,'Data Sheet'!D20:D24, -1*'Data Sheet'!D19) -> 229702.44 | E5: =SUM('Data Sheet'!E18,'Data Sheet'!E20:E24, -1*'Data Sheet'!E19) -> 265816.7 | F5: =SUM('Data Sheet'!F18,'Data Sheet'!F20:F24, -1*'Data Sheet'!F19) -> 346804.94 | G5: =SUM('Data Sheet'!G18,'Data Sheet'!G20:G24, -1*'Data Sheet'!G19) -> 344622.93 | H5: =SUM('Data Sheet'!H18,'Data Sheet'!H20:H24, -1*'Data Sheet'!H19) -> 254375.47 | I5: =SUM('Data Sheet'!I18,'Data Sheet'!I20:I24, -1*'Data Sheet'!I19) -> 411372.65 | ... K5: =SUM('Data Sheet'!K18,'Data Sheet'!K20:K24, -1*'Data Sheet'!K19) -> 488560.82 | L5: =SUM(Quarters!H5:K5) -> 569596.7 | M5: =M4-M6 -> 627202.28 | N5: =N4-N6 -> 550874.33
A6: Operating Profit | B6: =B4-B5 -> 42312.32 | C6: =C4-C5 -> 39134.63 | D6: =D4-D5 -> 52803.67 | E6: =E4-E5 -> 56889.06 | F6: =F4-F5 -> 74818.99 | G6: =G4-G5 -> 52104.98 | H6: =H4-H5 -> 49473.44 | I6: =I4-I5 -> 79873.59 | ... K6: =K4-K5 -> 102835.44 | L6: =SUM(Quarters!H6:K6) -> 89624.51 | M6: =M4*M24 -> 111187.26 | N6: =N4*N24 -> 86678.596
A7: Other Income | B7: ='Data Sheet'!B25 -> 5954.76 | C7: ='Data Sheet'!C25 -> 1067.26 | D7: ='Data Sheet'!D25 -> 12724.18 | E7: ='Data Sheet'!E25 -> 10429.39 | F7: ='Data Sheet'!F25 -> 9567.1 | G7: ='Data Sheet'!G25 -> 981.69 | H7: ='Data Sheet'!H25 -> 11270.51 | I7: ='Data Sheet'!I25 -> 6796.72 | ... K7: ='Data Sheet'!K25 -> 12981.54 | L7: =SUM(Quarters!H7:K7) -> 12738.76 | M7: 0 | N7: 0
A8: Depreciation | B8: ='Data Sheet'!B26 -> 18032.97 | C8: ='Data Sheet'!C26 -> 16384.06 | D8: ='Data Sheet'!D26 -> 20219.2 | E8: ='Data Sheet'!E26 -> 23111.91 | F8: ='Data Sheet'!F26 -> 23703.7 | G8: ='Data Sheet'!G26 -> 26634.88 | H8: ='Data Sheet'!H26 -> 25538.47 | I8: ='Data Sheet'!I26 -> 26883.16 | ... K8: ='Data Sheet'!K26 -> 28762.75 | L8: =SUM(Quarters!H8:K8) -> 34025.55 | M8: =+$L8 -> 34025.55 | N8: =+$L8 -> 34025.55
A9: Interest | B9: ='Data Sheet'!B27 -> 2863.75 | C9: ='Data Sheet'!C27 -> 3765.58 | D9: ='Data Sheet'!D27 -> 3591.11 | E9: ='Data Sheet'!E27 -> 4999.04 | F9: ='Data Sheet'!F27 -> 5836.73 | G9: ='Data Sheet'!G27 -> 7489.34 | H9: ='Data Sheet'!H27 -> 5079.03 | I9: ='Data Sheet'!I27 -> 5696.04 | ... K9: ='Data Sheet'!K27 -> 10194.17 | L9: =SUM(Quarters!H9:K9) -> 13717.4 | M9: =+$L9 -> 13717.4 | N9: =+$L9 -> 13717.4
A10: Profit before tax | B10: ='Data Sheet'!B28 -> 27370.36 | C10: ='Data Sheet'!C28 -> 20052.25 | D10: ='Data Sheet'!D28 -> 41717.54 | E10: ='Data Sheet'!E28 -> 39207.5 | F10: ='Data Sheet'!F28 -> 54845.66 | G10: ='Data Sheet'!G28 -> 18962.45 | H10: ='Data Sheet'!H28 -> 30126.45 | I10: ='Data Sheet'!I28 -> 54091.11 | ... K10: ='Data Sheet'!K28 -> 76860.06 | L10: =SUM(Quarters!H10:K10) -> 54620.32 | M10: =M6+M7-SUM(M8:M9) -> 63444.31 | N10: =N6+N7-SUM(N8:N9) -> 38935.646
A11: Tax | B11: ='Data Sheet'!B29 -> 9697.41 | C11: ='Data Sheet'!C29 -> 6950.7 | D11: ='Data Sheet'!D29 -> 12548.42 | E11: ='Data Sheet'!E29 -> 13139.52 | F11: ='Data Sheet'!F29 -> 20907.65 | G11: ='Data Sheet'!G29 -> 7506.19 | H11: ='Data Sheet'!H29 -> 8766.2 | I11: ='Data Sheet'!I29 -> 4797.04 | ... K11: ='Data Sheet'!K29 -> 19759.23 | L11: =SUM(Quarters!H11:K11) -> 13621.53 | M11: =IF($L10>0,$L11/$L10,0) -> 0.24938576 | N11: =IF($L10>0,$L11/$L10,0) -> 0.24938576
A12: Net profit | B12: ='Data Sheet'!B30 -> 18333.52 | C12: ='Data Sheet'!C30 -> 12875.21 | D12: ='Data Sheet'!D30 -> 24419.25 | E12: ='Data Sheet'!E30 -> 22105.93 | F12: ='Data Sheet'!F30 -> 30546.04 | G12: ='Data Sheet'!G30 -> 10803.6 | H12: ='Data Sheet'!H30 -> 16304.4 | I12: ='Data Sheet'!I30 -> 45522.11 | ... K12: ='Data Sheet'!K30 -> 49221.38 | L12: =SUM(Quarters!H12:K12) -> 39010.15 | M12: =M10-M11*M10 -> 47622.202 | N12: =N10-N11*N10 -> 29225.65
A13: EPS | B13: =IF('Data Sheet'!B93>0,B12/'Data Sheet'!B93,0) -> 14.286008 | C13: =IF('Data Sheet'!C93>0,C12/'Data Sheet'!C93,0) -> 10.032735 | D13: =IF('Data Sheet'!D93>0,D12/'Data Sheet'!D93,0) -> 19.028185 | E13: =IF('Data Sheet'!E93>0,E12/'Data Sheet'!E93,0) -> 17.225579 | F13: =IF('Data Sheet'!F93>0,F12/'Data Sheet'!F93,0) -> 24.280852 | G13: =IF('Data Sheet'!G93>0,G12/'Data Sheet'!G93,0) -> 8.5877125 | H13: =IF('Data Sheet'!H93>0,H12/'Data Sheet'!H93,0) -> 12.960263 | I13: =IF('Data Sheet'!I93>0,I12/'Data Sheet'!I93,0) -> 36.185234 | ... K13: =IF('Data Sheet'!K93>0,K12/'Data Sheet'!K93,0) -> 39.12576 | L13: =IF('Data Sheet'!$B6>0,'Profit & Loss'!L12/'Data Sheet'!$B6,0) -> 31.008954 | M13: =IF('Data Sheet'!$B6>0,'Profit & Loss'!M12/'Data Sheet'!$B6,0) -> 37.854627 | N13: =IF('Data Sheet'!$B6>0,'Profit & Loss'!N12/'Data Sheet'!$B6,0) -> 23.231309
A14: Price to earning | B14: =IF(B15>0,B15/B13,"") -> 14.295806 | C14: =IF(C15>0,C15/C13,"") -> 14.226429 | D14: =IF(D15>0,D15/D13,"") -> 9.7224198 | E14: =IF(E15>0,E15/E13,"") -> 10.321859 | F14: =IF(F15>0,F15/F13,"") -> 6.5792585 | G14: =IF(G15>0,G15/G13,"") -> 7.9532238 | H14: =IF(H15>0,H15/H13,"") -> 7.8817843 | I14: =IF(I15>0,I15/I13,"") -> 4.5294719 | ... K14: =IF(K15>0,K15/K13,"") -> 6.8509851 | L14: =IF(L13>0,L15/L13,0) -> 7.9767284 | M14: =M25 -> 7.9767284 | N14: =N25 -> 6.179751
A15: Price | B15: ='Data Sheet'!B90 -> 204.23 | C15: ='Data Sheet'!C90 -> 142.73 | D15: ='Data Sheet'!D90 -> 185 | E15: ='Data Sheet'!E90 -> 177.8 | F15: ='Data Sheet'!F90 -> 159.75 | G15: ='Data Sheet'!G90 -> 68.3 | H15: ='Data Sheet'!H90 -> 102.15 | I15: ='Data Sheet'!I90 -> 163.9 | ... K15: ='Data Sheet'!K90 -> 268.05 | L15: ='Data Sheet'!B8 -> 247.35 | M15: =M13*M14 -> 301.95607 | N15: =N13*N14 -> 143.5637
A17: RATIOS:
A18: Dividend Payout | B18: =IF('Data Sheet'!B30>0, 'Data Sheet'!B31/'Data Sheet'!B30, 0) -> 0.44332676 | C18: =IF('Data Sheet'!C30>0, 'Data Sheet'!C31/'Data Sheet'!C30, 0) -> 0.56482108 | D18: =IF('Data Sheet'!D30>0, 'Data Sheet'!D31/'Data Sheet'!D30, 0) -> 0.39678164 | E18: =IF('Data Sheet'!E30>0, 'Data Sheet'!E31/'Data Sheet'!E30, 0) -> 0.38315285 | F18: =IF('Data Sheet'!F30>0, 'Data Sheet'!F31/'Data Sheet'!F30, 0) -> 0.28829302 | G18: =IF('Data Sheet'!G30>0, 'Data Sheet'!G31/'Data Sheet'!G30, 0) -> 0.58222722 | H18: =IF('Data Sheet'!H30>0, 'Data Sheet'!H31/'Data Sheet'!H30, 0) -> 0.27777164 | I18: =IF('Data Sheet'!I30>0, 'Data Sheet'!I31/'Data Sheet'!I30, 0) -> 0.29017306 | ... K18: =IF('Data Sheet'!K30>0, 'Data Sheet'!K31/'Data Sheet'!K30, 0) -> 0.3130924
A19: OPM | B19: =IF(B6>0,B6/B4,0) -> 0.26293578 | C19: =IF(C6>0,C6/C4,0) -> 0.31551099 | D19: =IF(D6>0,D6/D4,0) -> 0.1869116 | E19: =IF(E6>0,E6/E4,0) -> 0.17628771 | F19: =IF(F6>0,F6/F4,0) -> 0.17745433 | G19: =IF(G6>0,G6/G4,0) -> 0.13133681 | H19: =IF(H6>0,H6/H4,0) -> 0.1628225 | I19: =IF(I6>0,I6/I4,0) -> 0.16259379 | ... L19: =IF(L6>0,L6/L4,0) -> 0.13595514
G22: TRENDS: | H22: 10 YEARS | I22: 7 YEARS | J22: 5 YEARS | K22: 3 YEARS | L22: RECENT | M22: BEST | N22: WORST
G23: Sales Growth | H23: =IF(B4=0,"",POWER($K4/B4,1/9)-1) -> 0.15559812 | I23: =IF(D4=0,"",POWER($K4/D4,1/7)-1) -> 0.11131153 | J23: =IF(F4=0,"",POWER($K4/F4,1/5)-1) -> 0.070016967 | K23: =IF(H4=0,"",POWER($K4/H4, 1/3)-1) -> 0.24855295 | L23: =IF(ISERROR(MAX(IF(J4=0,"",(K4-J4)/J4),IF(K4=0,"",(L4-K4)/K4))),"",MAX(IF(J4=0,"",(K4-J4)/J4),IF(K4=0,"",(L4-K4)/K4))) -> 0.11468613 | M23: =MAX(K23:L23) -> 0.24855295 | N23: =MIN(H23:L23) -> 0.070016967
G24: OPM | H24: =IF(SUM(B4:$K$4)=0,"",SUMPRODUCT(B19:$K$19,B4:$K$4)/SUM(B4:$K$4)) -> 0.16788891 | I24: =IF(SUM(E4:$K$4)=0,"",SUMPRODUCT(E19:$K$19,E4:$K$4)/SUM(E4:$K$4)) -> 0.15555296 | J24: =IF(SUM(G4:$K$4)=0,"",SUMPRODUCT(G19:$K$19,G4:$K$4)/SUM(G4:$K$4)) -> 0.14896 | K24: =IF(SUM(I4:$K$4)=0, "", SUMPRODUCT(I19:$K$19,I4:$K$4)/SUM(I4:$K$4)) -> 0.15058076 | L24: =L19 -> 0.13595514 | M24: =MAX(K24:L24) -> 0.15058076 | N24: =MIN(H24:L24) -> 0.13595514
G25: Price to Earning | H25: =IF(ISERROR(AVERAGEIF(B14:$L14,">0")),"",AVERAGEIF(B14:$L14,">0")) -> 8.6999804 | I25: =IF(ISERROR(AVERAGEIF(E14:$L14,">0")),"",AVERAGEIF(E14:$L14,">0")) -> 7.1818912 | J25: =IF(ISERROR(AVERAGEIF(G14:$L14,">0")),"",AVERAGEIF(G14:$L14,">0")) -> 6.7590021 | K25: =IF(ISERROR(AVERAGEIF(I14:$L14,">0")),"",AVERAGEIF(I14:$L14,">0")) -> 6.179751 | L25: =L14 -> 7.9767284 | M25: =MAX(K25:L25) -> 7.9767284 | N25: =MIN(H25:L25) -> 6.179751

Sheet Quarters
A1: ='Profit & Loss'!A1 -> OIL & NATURAL GAS CORPN LTD | E1: =UPDATE | J1: SCREENER.IN
A3: Narration | B3: ='Data Sheet'!B41 -> 44834 | C3: ='Data Sheet'!C41 -> 44926 | D3: ='Data Sheet'!D41 -> 45016 | E3: ='Data Sheet'!E41 -> 45107 | F3: ='Data Sheet'!F41 -> 45199 | G3: ='Data Sheet'!G41 -> 45291 | H3: ='Data Sheet'!H41 -> 45382 | I3: ='Data Sheet'!I41 -> 45473 | ... K3: ='Data Sheet'!K41 -> 45657
A4: Sales | B4: ='Data Sheet'!B42 -> 168656.12 | C4: ='Data Sheet'!C42 -> 169212.63 | D4: ='Data Sheet'!D42 -> 164066.72 | E4: ='Data Sheet'!E42 -> 163823.59 | F4: ='Data Sheet'!F42 -> 147613.68 | G4: ='Data Sheet'!G42 -> 167356.63 | H4: ='Data Sheet'!H42 -> 166770.63 | I4: ='Data Sheet'!I42 -> 168024.8 | ... K4: ='Data Sheet'!K42 -> 166096.68
A5: Expenses | B5: ='Data Sheet'!B43 -> 155310.59 | C5: ='Data Sheet'!C43 -> 147345.52 | D5: ='Data Sheet'!D43 -> 143527.29 | E5: ='Data Sheet'!E43 -> 133028.63 | F5: ='Data Sheet'!F43 -> 119533.64 | G5: ='Data Sheet'!G43 -> 146996.46 | H5: ='Data Sheet'!H43 -> 143545.42 | I5: ='Data Sheet'!I43 -> 146398.25 | ... K5: ='Data Sheet'!K43 -> 141818.62
A6: Operating Profit | B6: ='Data Sheet'!B50 -> 13345.53 | C6: ='Data Sheet'!C50 -> 21867.11 | D6: ='Data Sheet'!D50 -> 20539.43 | E6: ='Data Sheet'!E50 -> 30794.96 | F6: ='Data Sheet'!F50 -> 28080.04 | G6: ='Data Sheet'!G50 -> 20360.17 | H6: ='Data Sheet'!H50 -> 23225.21 | I6: ='Data Sheet'!I50 -> 21626.55 | ... K6: ='Data Sheet'!K50 -> 24278.06
A7: Other Income | B7: ='Data Sheet'!B44 -> 2314.59 | C7: ='Data Sheet'!C44 -> 2807.3 | D7: ='Data Sheet'!D44 -> -4786.26 | E7: ='Data Sheet'!E44 -> 3069.28 | F7: ='Data Sheet'!F44 -> 3672.87 | G7: ='Data Sheet'!G44 -> 4299.03 | H7: ='Data Sheet'!H44 -> 2548.87 | I7: ='Data Sheet'!I44 -> 3615.38 | ... K7: ='Data Sheet'!K44 -> 2411.09
A8: Depreciation | B8: ='Data Sheet'!B45 -> 4442.76 | C8: ='Data Sheet'!C45 -> 6784.01 | D8: ='Data Sheet'!D45 -> 6743.59 | E8: ='Data Sheet'!E45 -> 7078.28 | F8: ='Data Sheet'!F45 -> 7078.57 | G8: ='Data Sheet'!G45 -> 7494.27 | H8: ='Data Sheet'!H45 -> 7862.89 | I8: ='Data Sheet'!I45 -> 8456.43 | ... K8: ='Data Sheet'!K45 -> 9497.22
A9: Interest | B9: ='Data Sheet'!B46 -> 1992.94 | C9: ='Data Sheet'!C46 -> 2188.43 | D9: ='Data Sheet'!D46 -> 2068.11 | E9: ='Data Sheet'!E46 -> 2363.94 | F9: ='Data Sheet'!F46 -> 3243.32 | G9: ='Data Sheet'!G46 -> 3203.18 | H9: ='Data Sheet'!H46 -> 2682.77 | I9: ='Data Sheet'!I46 -> 3615.9 | ... K9: ='Data Sheet'!K46 -> 3669.74
A10: Profit before tax | B10: ='Data Sheet'!B47 -> 9224.42 | C10: ='Data Sheet'!C47 -> 15701.97 | D10: ='Data Sheet'!D47 -> 6941.47 | E10: ='Data Sheet'!E47 -> 24422.02 | F10: ='Data Sheet'!F47 -> 21431.02 | G10: ='Data Sheet'!G47 -> 13961.75 | H10: ='Data Sheet'!H47 -> 15228.42 | I10: ='Data Sheet'!I47 -> 13169.6 | ... K10: ='Data Sheet'!K47 -> 13522.19
A11: Tax | B11: ='Data Sheet'!B48 -> 2394.26 | C11: ='Data Sheet'!C48 -> 4036.73 | D11: ='Data Sheet'!D48 -> 463.24 | E11: ='Data Sheet'!E48 -> 6528.54 | F11: ='Data Sheet'!F48 -> 5259.72 | G11: ='Data Sheet'!G48 -> 3450.52 | H11: ='Data Sheet'!H48 -> 3701.89 | I11: ='Data Sheet'!I48 -> 3359.42 | ... K11: ='Data Sheet'!K48 -> 3738.55
A12: Net profit | B12: ='Data Sheet'!B49 -> 8299.37 | C12: ='Data Sheet'!C49 -> 11488.99 | D12: ='Data Sheet'!D49 -> 4492.25 | E12: ='Data Sheet'!E49 -> 14644.43 | F12: ='Data Sheet'!F49 -> 13703.38 | G12: ='Data Sheet'!G49 -> 10703.17 | H12: ='Data Sheet'!H49 -> 10107.36 | I12: ='Data Sheet'!I49 -> 10008.6 | ... K12: ='Data Sheet'!K49 -> 8621.69
A14: OPM | B14: =IF(B4>0,B6/B4,"") -> 0.079128644 | C14: =IF(C4>0,C6/C4,"") -> 0.12922859 | D14: =IF(D4>0,D6/D4,"") -> 0.1251895 | E14: =IF(E4>0,E6/E4,"") -> 0.18797635 | F14: =IF(F4>0,F6/F4,"") -> 0.19022654 | G14: =IF(G4>0,G6/G4,"") -> 0.12165739 | H14: =IF(H4>0,H6/H4,"") -> 0.13926439 | I14: =IF(I4>0,I6/I4,"") -> 0.12871046 | ... K14: =IF(K4>0,K6/K4,"") -> 0.14616824

Sheet Balance Sheet
A1: ='Profit & Loss'!A1 -> OIL & NATURAL GAS CORPN LTD | E1: =UPDATE | J1: SCREENER.IN
A3: Narration | B3: ='Data Sheet'!B56 -> 42094 | C3: ='Data Sheet'!C56 -> 42460 | D3: ='Data Sheet'!D56 -> 42825 | E3: ='Data Sheet'!E56 -> 43190 | F3: ='Data Sheet'!F56 -> 43555 | G3: ='Data Sheet'!G56 -> 43921 | H3: ='Data Sheet'!H56 -> 44286 | I3: ='Data Sheet'!I56 -> 44651 | ... K3: ='Data Sheet'!K56 -> 45382
A4: Equity Share Capital | B4: ='Data Sheet'!B57 -> 4277.76 | C4: ='Data Sheet'!C57 -> 4277.76 | D4: ='Data Sheet'!D57 -> 6416.63 | E4: ='Data Sheet'!E57 -> 6416.63 | F4: ='Data Sheet'!F57 -> 6290.15 | G4: ='Data Sheet'!G57 -> 6290.15 | H4: ='Data Sheet'!H57 -> 6290.14 | I4: ='Data Sheet'!I57 -> 6290.14 | ... K4: ='Data Sheet'!K57 -> 6290.14
A5: Reserves | B5: ='Data Sheet'!B58 -> 176176.64 | C5: ='Data Sheet'!C58 -> 193535.88 | D5: ='Data Sheet'!D58 -> 187968.59 | E5: ='Data Sheet'!E58 -> 197602.3 | F5: ='Data Sheet'!F58 -> 210644.5 | G5: ='Data Sheet'!G58 -> 198814.45 | H5: ='Data Sheet'!H58 -> 214690.85 | I5: ='Data Sheet'!I58 -> 253212.77 | ... K5: ='Data Sheet'!K58 -> 330780.09
A6: Borrowings | B6: ='Data Sheet'!B59 -> 53944.47 | C6: ='Data Sheet'!C59 -> 45500.17 | D6: ='Data Sheet'!D59 -> 80029.27 | E6: ='Data Sheet'!E59 -> 106549.94 | F6: ='Data Sheet'!F59 -> 107741.69 | G6: ='Data Sheet'!G59 -> 129472.52 | H6: ='Data Sheet'!H59 -> 133186.92 | I6: ='Data Sheet'!I59 -> 121985.86 | ... K6: ='Data Sheet'!K59 -> 153180.53
A7: Other Liabilities | B7: ='Data Sheet'!B60 -> 103447.69 | C7: ='Data Sheet'!C60 -> 98458.57 | D7: ='Data Sheet'!D60 -> 170110.83 | E7: ='Data Sheet'!E60 -> 148663.53 | F7: ='Data Sheet'!F60 -> 167666.95 | G7: ='Data Sheet'!G60 -> 173786.92 | H7: ='Data Sheet'!H60 -> 187579.74 | I7: ='Data Sheet'!I60 -> 201770.75 | ... K7: ='Data Sheet'!K60 -> 219523.17
A8: Total | B8: ='Data Sheet'!B61 -> 337846.56 | C8: ='Data Sheet'!C61 -> 341772.38 | D8: ='Data Sheet'!D61 -> 444525.32 | E8: ='Data Sheet'!E61 -> 459232.4 | F8: ='Data Sheet'!F61 -> 492343.29 | G8: ='Data Sheet'!G61 -> 508364.04 | H8: ='Data Sheet'!H61 -> 541747.65 | I8: ='Data Sheet'!I61 -> 583259.52 | ... K8: ='Data Sheet'!K61 -> 709773.93
A10: Net Block | B10: ='Data Sheet'!B62 -> 179932.96 | C10: ='Data Sheet'!C62 -> 166276.73 | D10: ='Data Sheet'!D62 -> 211125.43 | E10: ='Data Sheet'!E62 -> 226057.68 | F10: ='Data Sheet'!F62 -> 230390.7 | G10: ='Data Sheet'!G62 -> 243891.96 | H10: ='Data Sheet'!H62 -> 243746.36 | I10: ='Data Sheet'!I62 -> 254402.17 | ... K10: ='Data Sheet'!K62 -> 298454.36
A11: Capital Work in Progress | B11: ='Data Sheet'!B63 -> 63393.37 | C11: ='Data Sheet'!C63 -> 57668.48 | D11: ='Data Sheet'!D63 -> 59042.48 | E11: ='Data Sheet'!E63 -> 61511.87 | F11: ='Data Sheet'!F63 -> 69056.44 | G11: ='Data Sheet'!G63 -> 83832.4 | H11: ='Data Sheet'!H63 -> 100308.82 | I11: ='Data Sheet'!I63 -> 106719.23 | ... K11: ='Data Sheet'!K63 -> 116021.68
A12: Investments | B12: ='Data Sheet'!B64 -> 4749.14 | C12: ='Data Sheet'!C64 -> 33386.85 | D12: ='Data Sheet'!D64 -> 70745.67 | E12: ='Data Sheet'!E64 -> 67334.61 | F12: ='Data Sheet'!F64 -> 66908.92 | G12: ='Data Sheet'!G64 -> 56755.18 | H12: ='Data Sheet'!H64 -> 60320.36 | I12: ='Data Sheet'!I64 -> 66642.14 | ... K12: ='Data Sheet'!K64 -> 102207.2
A13: Other Assets | B13: ='Data Sheet'!B65 -> 89771.09 | C13: ='Data Sheet'!C65 -> 84440.32 | D13: ='Data Sheet'!D65 -> 103611.74 | E13: ='Data Sheet'!E65 -> 104328.24 | F13: ='Data Sheet'!F65 -> 125987.23 | G13: ='Data Sheet'!G65 -> 123884.5 | H13: ='Data Sheet'!H65 -> 137372.11 | I13: ='Data Sheet'!I65 -> 155495.98 | ... K13: ='Data Sheet'!K65 -> 193090.69
A14: Total | B14: ='Data Sheet'!B66 -> 337846.56 | C14: ='Data Sheet'!C66 -> 341772.38 | D14: ='Data Sheet'!D66 -> 444525.32 | E14: ='Data Sheet'!E66 -> 459232.4 | F14: ='Data Sheet'!F66 -> 492343.29 | G14: ='Data Sheet'!G66 -> 508364.04 | H14: ='Data Sheet'!H66 -> 541747.65 | I14: ='Data Sheet'!I66 -> 583259.52 | ... K14: ='Data Sheet'!K66 -> 709773.93
A16: Working Capital | B16: =B13-B7 -> -13676.6 | C16: =C13-C7 -> -14018.25 | D16: =D13-D7 -> -66499.09 | E16: =E13-E7 -> -44335.29 | F16: =F13-F7 -> -41679.72 | G16: =G13-G7 -> -49902.42 | H16: =H13-H7 -> -50207.63 | I16: =I13-I7 -> -46274.77 | ... K16: =K13-K7 -> -26432.48
A17: Debtors | B17: ='Data Sheet'!B67 -> 18815.82 | C17: ='Data Sheet'!C67 -> 8331.71 | D17: ='Data Sheet'!D67 -> 12547.12 | E17: ='Data Sheet'!E67 -> 13899.17 | F17: ='Data Sheet'!F67 -> 15396.46 | G17: ='Data Sheet'!G67 -> 9173.41 | H17: ='Data Sheet'!H67 -> 16015.83 | I17: ='Data Sheet'!I67 -> 19187.28 | ... K17: ='Data Sheet'!K67 -> 19762.95
A18: Inventory | B18: ='Data Sheet'!B68 -> 11354.86 | C18: ='Data Sheet'!C68 -> 10761.97 | D18: ='Data Sheet'!D68 -> 30555.38 | E18: ='Data Sheet'!E68 -> 31253.57 | F18: ='Data Sheet'!F68 -> 35949.41 | G18: ='Data Sheet'!G68 -> 34065.12 | H18: ='Data Sheet'!H68 -> 45735.85 | I18: ='Data Sheet'!I68 -> 55360.27 | ... K18: ='Data Sheet'!K68 -> 53255.24
A20: Debtor Days | B20: =IF('Profit & Loss'!B4>0,'Balance Sheet'!B17/('Profit & Loss'!B4/365),0) -> 42.67749 | C20: =IF('Profit & Loss'!C4>0,'Balance Sheet'!C17/('Profit & Loss'!C4/365),0) -> 24.517731 | D20: =IF('Profit & Loss'!D4>0,'Balance Sheet'!D17/('Profit & Loss'!D4/365),0) -> 16.210973 | E20: =IF('Profit & Loss'!E4>0,'Balance Sheet'!E17/('Profit & Loss'!E4/365),0) -> 15.720813 | F20: =IF('Profit & Loss'!F4>0,'Balance Sheet'!F17/('Profit & Loss'!F4/365),0) -> 13.328721 | G20: =IF('Profit & Loss'!G4>0,'Balance Sheet'!G17/('Profit & Loss'!G4/365),0) -> 8.4397759 | H20: =IF('Profit & Loss'!H4>0,'Balance Sheet'!H17/('Profit & Loss'!H4/365),0) -> 19.239095 | I20: =IF('Profit & Loss'!I4>0,'Balance Sheet'!I17/('Profit & Loss'!I4/365),0) -> 14.256307 | ... K20: =IF('Profit & Loss'!K4>0,'Balance Sheet'!K17/('Profit & Loss'!K4/365),0) -> 12.197366
A21: Inventory Turnover | B21: =IF('Balance Sheet'!B18>0,'Profit & Loss'!B4/'Balance Sheet'!B18,0) -> 14.172138 | C21: =IF('Balance Sheet'!C18>0,'Profit & Loss'!C4/'Balance Sheet'!C18,0) -> 11.525372 | D21: =IF('Balance Sheet'!D18>0,'Profit & Loss'!D4/'Balance Sheet'!D18,0) -> 9.2457076 | E21: =IF('Balance Sheet'!E18>0,'Profit & Loss'!E4/'Balance Sheet'!E18,0) -> 10.325405 | F21: =IF('Balance Sheet'!F18>0,'Profit & Loss'!F4/'Balance Sheet'!F18,0) -> 11.728257 | G21: =IF('Balance Sheet'!G18>0,'Profit & Loss'!G4/'Balance Sheet'!G18,0) -> 11.646162 | H21: =IF('Balance Sheet'!H18>0,'Profit & Loss'!H4/'Balance Sheet'!H18,0) -> 6.643561 | I21: =IF('Balance Sheet'!I18>0,'Profit & Loss'!I4/'Balance Sheet'!I18,0) -> 8.8736244 | ... K21: =IF('Balance Sheet'!K18>0,'Profit & Loss'!K4/'Balance Sheet'!K18,0) -> 11.10494
A23: Return on Equity | B23: =IF(SUM('Balance Sheet'!B4:B5)>0,'Profit & Loss'!B12/SUM('Balance Sheet'!B4:B5),"") -> 0.10159641 | C23: =IF(SUM('Balance Sheet'!C4:C5)>0,'Profit & Loss'!C12/SUM('Balance Sheet'!C4:C5),"") -> 0.065087574 | D23: =IF(SUM('Balance Sheet'!D4:D5)>0,'Profit & Loss'!D12/SUM('Balance Sheet'!D4:D5),"") -> 0.12562298 | E23: =IF(SUM('Balance Sheet'!E4:E5)>0,'Profit & Loss'!E12/SUM('Balance Sheet'!E4:E5),"") -> 0.10835235 | F23: =IF(SUM('Balance Sheet'!F4:F5)>0,'Profit & Loss'!F12/SUM('Balance Sheet'!F4:F5),"") -> 0.14080757 | G23: =IF(SUM('Balance Sheet'!G4:G5)>0,'Profit & Loss'!G12/SUM('Balance Sheet'!G4:G5),"") -> 0.052673611 | H23: =IF(SUM('Balance Sheet'!H4:H5)>0,'Profit & Loss'!H12/SUM('Balance Sheet'!H4:H5),"") -> 0.073781912 | I23: =IF(SUM('Balance Sheet'!I4:I5)>0,'Profit & Loss'!I12/SUM('Balance Sheet'!I4:I5),"") -> 0.17542042 | ... K23: =IF(SUM('Balance Sheet'!K4:K5)>0,'Profit & Loss'!K12/SUM('Balance Sheet'!K4:K5),"") -> 0.14602708
A24: Return on Capital Emp | C24: =IF((B4+B5+B6+C4+C5+C6)>0,('Profit & Loss'!C10+'Profit & Loss'!C9)*2/(B4+B5+B6+C4+C5+C6),"") -> 0.099716131 | D24: =IF((C4+C5+C6+D4+D5+D6)>0,('Profit & Loss'!D10+'Profit & Loss'!D9)*2/(C4+C5+C6+D4+D5+D6),"") -> 0.17502868 | E24: =IF((D4+D5+D6+E4+E5+E6)>0,('Profit & Loss'!E10+'Profit & Loss'!E9)*2/(D4+D5+D6+E4+E5+E6),"") -> 0.15113777 | F24: =IF((E4+E5+E6+F4+F5+F6)>0,('Profit & Loss'!F10+'Profit & Loss'!F9)*2/(E4+E5+E6+F4+F5+F6),"") -> 0.19105186 | G24: =IF((F4+F5+F6+G4+G5+G6)>0,('Profit & Loss'!G10+'Profit & Loss'!G9)*2/(F4+F5+F6+G4+G5+G6),"") -> 0.080247709 | H24: =IF((G4+G5+G6+H4+H5+H6)>0,('Profit & Loss'!H10+'Profit & Loss'!H9)*2/(G4+G5+G6+H4+H5+H6),"") -> 0.10223081 | I24: =IF((H4+H5+H6+I4+I5+I6)>0,('Profit & Loss'!I10+'Profit & Loss'!I9)*2/(H4+H5+H6+I4+I5+I6),"") -> 0.1625409 | J24: =IF((I4+I5+I6+J4+J5+J6)>0,('Profit & Loss'!J10+'Profit & Loss'!J9)*2/(I4+I5+I6+J4+J5+J6),"") -> 0.12665512 | K24: =IF((J4+J5+J6+K4+K5+K6)>0,('Profit & Loss'!K10+'Profit & Loss'!K9)*2/(J4+J5+J6+K4+K5+K6),"") -> 0.19066737

Sheet Cash Flow
A1: ='Balance Sheet'!A1 -> OIL & NATURAL GAS CORPN LTD | E1: =UPDATE | J1: SCREENER.IN
A3: Narration | B3: ='Data Sheet'!B81 -> 42094 | C3: ='Data Sheet'!C81 -> 42460 | D3: ='Data Sheet'!D81 -> 42825 | E3: ='Data Sheet'!E81 -> 43190 | F3: ='Data Sheet'!F81 -> 43555 | G3: ='Data Sheet'!G81 -> 43921 | H3: ='Data Sheet'!H81 -> 44286 | I3: ='Data Sheet'!I81 -> 44651 | ... K3: ='Data Sheet'!K81 -> 45382
A4: Cash from Operating Activity | B4: ='Data Sheet'!B82 -> 33950.42 | C4: ='Data Sheet'!C82 -> 46292.49 | D4: ='Data Sheet'!D82 -> 45780.48 | E4: ='Data Sheet'!E82 -> 56792.1 | F4: ='Data Sheet'!F82 -> 61457.6 | G4: ='Data Sheet'!G82 -> 70592.98 | H4: ='Data Sheet'!H82 -> 47185.19 | I4: ='Data Sheet'!I82 -> 78248.25 | ... K4: ='Data Sheet'!K82 -> 99262.69
A5: Cash from Investing Activity | B5: ='Data Sheet'!B83 -> -30058.33 | C5: ='Data Sheet'!C83 -> -38255.87 | D5: ='Data Sheet'!D83 -> -43814.55 | E5: ='Data Sheet'!E83 -> -66798.14 | F5: ='Data Sheet'!F83 -> -37131.63 | G5: ='Data Sheet'!G83 -> -53159.05 | H5: ='Data Sheet'!H83 -> -39141.15 | I5: ='Data Sheet'!I83 -> -41197.15 | ... K5: ='Data Sheet'!K83 -> -57203.42
A6: Cash from Financing Activity | B6: ='Data Sheet'!B84 -> -10640.78 | C6: ='Data Sheet'!C84 -> -8972 | D6: ='Data Sheet'!D84 -> -1867.05 | E6: ='Data Sheet'!E84 -> 9909.36 | F6: ='Data Sheet'!F84 -> -23324.5 | G6: ='Data Sheet'!G84 -> -16726.36 | H6: ='Data Sheet'!H84 -> -8239.48 | I6: ='Data Sheet'!I84 -> -35790.02 | ... K6: ='Data Sheet'!K84 -> -45650.29
A7: Net Cash Flow | B7: ='Data Sheet'!B85 -> -6748.68 | C7: ='Data Sheet'!C85 -> -935.38 | D7: ='Data Sheet'!D85 -> 98.87 | E7: ='Data Sheet'!E85 -> -96.69 | F7: ='Data Sheet'!F85 -> 1001.47 | G7: ='Data Sheet'!G85 -> 707.57 | H7: ='Data Sheet'!H85 -> -195.44 | I7: ='Data Sheet'!I85 -> 1261.09 | ... K7: ='Data Sheet'!K85 -> -3591.02

Sheet Customization
A1: How to use it?
A3: You can customize this workbook as you want.
B4: You can add custom formating, add conditional formating, add your own formulas… do ANYTHING.
B5: Please don't edit the "Data Sheet" only.
A7: After customization, you can upload this back on Screener.
B8: Upload on: | C8: https://www.screener.in/excel/
A10: Download your customized workbooks now onwards.
B11: Now whenever you will "Export to excel" from Screener, it will export your customized file.
A14: TESTING:
B15: This is a testing feature currently.
B16: You can report any formula errors on the worksheet at: support@screener.in

Sheet Historical FS
B2: ="Historical Financial Statement - "&'Profit & Loss'!A1 -> Historical Financial Statement - OIL & NATURAL GAS CORPN LTD
B3: Years | C3: =Annual[[#This Row],[Column2]] -> 42094 | D3: =Annual[[#This Row],[Column3]] -> 42460 | E3: =Annual[[#This Row],[Column4]] -> 42825 | F3: =Annual[[#This Row],[Column5]] -> 43190 | G3: =Annual[[#This Row],[Column6]] -> 43555 | H3: =Annual[[#This Row],[Column7]] -> 43921 | I3: =Annual[[#This Row],[Column8]] -> 44286 | J3: =Annual[[#This Row],[Column9]] -> 44651 | K3: =Annual[[#This Row],[Column10]] -> 45016 | L3: =Annual[[#This Row],[Column11]] -> 45382 | M3: LTM
A5: # | B5: Income Statement
B7: Sales | C7: =IFERROR('Profit & Loss'!B4,0) -> 160922.64 | D7: =IFERROR('Profit & Loss'!C4,0) -> 124035.71 | E7: =IFERROR('Profit & Loss'!D4,0) -> 282506.11 | F7: =IFERROR('Profit & Loss'!E4,0) -> 322705.76 | G7: =IFERROR('Profit & Loss'!F4,0) -> 421623.93 | H7: =IFERROR('Profit & Loss'!G4,0) -> 396727.91 | I7: =IFERROR('Profit & Loss'!H4,0) -> 303848.91 | J7: =IFERROR('Profit & Loss'!I4,0) -> 491246.24 | ... L7: =IFERROR('Profit & Loss'!K4,0) -> 591396.26 | M7: =IFERROR(SUM(Quarters!H4:K4),0) -> 659221.21
B8: Sales Growth(y-o-y) | C8: - | D8: =D7/C7 -1 -> -0.22922151 | E8: =E7/D7 -1 -> 1.2776192 | F8: =F7/E7 -1 -> 0.14229657 | G8: =G7/F7 -1 -> 0.30652744 | H8: =H7/G7 -1 -> -0.059047929 | I8: =I7/H7 -1 -> -0.23411259 | J8: =J7/I7 -1 -> 0.61674511 | K8: =K7/J7 -1 -> 0.28711658 | ... M8: =M7/L7 -1 -> 0.11468613
B10: COGS | C10: =IFERROR(SUM('Data Sheet'!B18,'Data Sheet'!B20:B22)-1*'Data Sheet'!B19,0) -> 82045.1 | D10: =IFERROR(SUM('Data Sheet'!C18,'Data Sheet'!C20:C22)-1*'Data Sheet'!C19,0) -> 56921.45 | E10: =IFERROR(SUM('Data Sheet'!D18,'Data Sheet'!D20:D22)-1*'Data Sheet'!D19,0) -> 203938.19 | F10: =IFERROR(SUM('Data Sheet'!E18,'Data Sheet'!E20:E22)-1*'Data Sheet'!E19,0) -> 237810.82 | G10: =IFERROR(SUM('Data Sheet'!F18,'Data Sheet'!F20:F22)-1*'Data Sheet'!F19,0) -> 309596.56 | H10: =IFERROR(SUM('Data Sheet'!G18,'Data Sheet'!G20:G22)-1*'Data Sheet'!G19,0) -> 309680.76 | I10: =IFERROR(SUM('Data Sheet'!H18,'Data Sheet'!H20:H22)-1*'Data Sheet'!H19,0) -> 231708.14 | J10: =IFERROR(SUM('Data Sheet'!I18,'Data Sheet'!I20:I22)-1*'Data Sheet'!I19,0) -> 377208.46 | ... L10: =IFERROR(SUM('Data Sheet'!K18,'Data Sheet'!K20:K22)-1*'Data Sheet'!K19,0) -> 453414.86 | M10: =IFERROR(SUM('Data Sheet'!H43:K43),0) -> 569596.7
B11: COGS % of sales | C11: =C10/C7 -> 0.50984187 | D11: =D10/D7 -> 0.45891179 | E11: =E10/E7 -> 0.72188948 | F11: =F10/F7 -> 0.73692772 | G11: =G10/G7 -> 0.73429551 | H11: =H10/H7 -> 0.78058728 | I11: =I10/I7 -> 0.76257683 | J11: =J10/J7 -> 0.76786025 | ... M11: =M10/M7 -> 0.86404486
B13: Gross Profit | C13: =C7-C10 -> 78877.54 | D13: =D7-D10 -> 67114.26 | E13: =E7-E10 -> 78567.92 | F13: =F7-F10 -> 84894.94 | G13: =G7-G10 -> 112027.37 | H13: =H7-H10 -> 87047.15 | I13: =I7-I10 -> 72140.77 | J13: =J7-J10 -> 114037.78 | ... M13: =M7-M10 -> 89624.51
B14: Gross Profit Margin % of sales | C14: =C13/C7 -> 0.49015813 | D14: =D13/D7 -> 0.54108821 | E14: =E13/E7 -> 0.27811052 | F14: =F13/F7 -> 0.26307228 | G14: =G13/G7 -> 0.26570449 | H14: =H13/H7 -> 0.21941272 | I14: =I13/I7 -> 0.23742317 | J14: =J13/J7 -> 0.23213975 | ... M14: =M13/M7 -> 0.13595514
B16: Selling and General Expenses | C16: =IFERROR(SUM('Data Sheet'!B23:B24),0) -> 36565.22 | D16: =IFERROR(SUM('Data Sheet'!C23:C24),0) -> 27979.63 | E16: =IFERROR(SUM('Data Sheet'!D23:D24),0) -> 25764.25 | F16: =IFERROR(SUM('Data Sheet'!E23:E24),0) -> 28005.88 | G16: =IFERROR(SUM('Data Sheet'!F23:F24),0) -> 37208.38 | H16: =IFERROR(SUM('Data Sheet'!G23:G24),0) -> 34942.17 | I16: =IFERROR(SUM('Data Sheet'!H23:H24),0) -> 22667.33 | J16: =IFERROR(SUM('Data Sheet'!I23:I24),0) -> 34164.19 | ... M16: =IFERROR(SUM('Data Sheet'!L23:L24),0) -> 0
B17: S&G Expenses % of sales | C17: =C16/C7 -> 0.22722235 | D17: =D16/D7 -> 0.22557721 | E17: =E16/E7 -> 0.091198912 | F17: =F16/F7 -> 0.086784568 | G17: =G16/G7 -> 0.088250162 | H17: =H16/H7 -> 0.088075906 | I17: =I16/I7 -> 0.074600663 | J17: =J16/J7 -> 0.069545957 | ... M17: =M16/M7 -> 0
B19: EBITDA | C19: =C13-C16 -> 42312.32 | D19: =D13-D16 -> 39134.63 | E19: =E13-E16 -> 52803.67 | F19: =F13-F16 -> 56889.06 | G19: =G13-G16 -> 74818.99 | H19: =H13-H16 -> 52104.98 | I19: =I13-I16 -> 49473.44 | J19: =J13-J16 -> 79873.59 | ... M19: =M13-M16 -> 89624.51
B20: EBITDA % of sales | C20: =C19/C7 -> 0.26293578 | D20: =D19/D7 -> 0.31551099 | E20: =E19/E7 -> 0.1869116 | F20: =F19/F7 -> 0.17628771 | G20: =G19/G7 -> 0.17745433 | H20: =H19/H7 -> 0.13133681 | I20: =I19/I7 -> 0.1628225 | J20: =J19/J7 -> 0.16259379 | ... M20: =M19/M7 -> 0.13595514
B22: Interest | C22: =IFERROR('Data Sheet'!B27,0) -> 2863.75 | D22: =IFERROR('Data Sheet'!C27,0) -> 3765.58 | E22: =IFERROR('Data Sheet'!D27,0) -> 3591.11 | F22: =IFERROR('Data Sheet'!E27,0) -> 4999.04 | G22: =IFERROR('Data Sheet'!F27,0) -> 5836.73 | H22: =IFERROR('Data Sheet'!G27,0) -> 7489.34 | I22: =IFERROR('Data Sheet'!H27,0) -> 5079.03 | J22: =IFERROR('Data Sheet'!I27,0) -> 5696.04 | ... L22: =IFERROR('Data Sheet'!K27,0) -> 10194.17 | M22: =IFERROR(SUM('Data Sheet'!H46:K46),0) -> 13717.4
B23: Interest % of sales | C23: =C22/C7 -> 0.017795818 | D23: =D22/D7 -> 0.030358838 | E23: =E22/E7 -> 0.012711619 | F23: =F22/F7 -> 0.015491016 | G23: =G22/G7 -> 0.01384345 | H23: =H22/H7 -> 0.018877774 | I23: =I22/I7 -> 0.016715643 | J23: =J22/J7 -> 0.011595081 | ... M23: =M22/M7 -> 0.020808493
B25: Depreciation | C25: =IFERROR('Data Sheet'!B26,0) -> 18032.97 | D25: =IFERROR('Data Sheet'!C26,0) -> 16384.06 | E25: =IFERROR('Data Sheet'!D26,0) -> 20219.2 | F25: =IFERROR('Data Sheet'!E26,0) -> 23111.91 | G25: =IFERROR('Data Sheet'!F26,0) -> 23703.7 | H25: =IFERROR('Data Sheet'!G26,0) -> 26634.88 | I25: =IFERROR('Data Sheet'!H26,0) -> 25538.47 | J25: =IFERROR('Data Sheet'!I26,0) -> 26883.16 | ... L25: =IFERROR('Data Sheet'!K26,0) -> 28762.75 | M25: =IFERROR(SUM('Data Sheet'!H45:K45),0) -> 34025.55
B26: Depreciation % of sales | C26: =C25/C7 -> 0.11205987 | D26: =D25/D7 -> 0.13209148 | E26: =E25/E7 -> 0.071570841 | F26: =F25/F7 -> 0.071619143 | G26: =G25/G7 -> 0.056220006 | H26: =H25/H7 -> 0.067136391 | I26: =I25/I7 -> 0.084049898 | J26: =J25/J7 -> 0.054724409 | ... M26: =M25/M7 -> 0.051614768
B28: EBT | C28: =IFERROR(C19-SUM(C25+C22),0) -> 21415.6 | D28: =IFERROR(D19-SUM(D25+D22),0) -> 18984.99 | E28: =IFERROR(E19-SUM(E25+E22),0) -> 28993.36 | F28: =IFERROR(F19-SUM(F25+F22),0) -> 28778.11 | G28: =IFERROR(G19-SUM(G25+G22),0) -> 45278.56 | H28: =IFERROR(H19-SUM(H25+H22),0) -> 17980.76 | I28: =IFERROR(I19-SUM(I25+I22),0) -> 18855.94 | J28: =IFERROR(J19-SUM(J25+J22),0) -> 47294.39 | ... L28: =IFERROR(L19-SUM(L25+L22),0) -> 63878.52 | M28: =IFERROR(SUM('Data Sheet'!H47:K47),0) -> 54620.32
B29: EBT % of sales | C29: =C28/C7 -> 0.13308009 | D29: =D28/D7 -> 0.15306068 | E29: =E28/E7 -> 0.10262914 | F29: =F28/F7 -> 0.089177553 | G29: =G28/G7 -> 0.10739087 | H29: =H28/H7 -> 0.045322649 | I29: =I28/I7 -> 0.062056961 | J29: =J28/J7 -> 0.096274304 | ... M29: =M28/M7 -> 0.082855829
B31: Tax | C31: =IFERROR('Data Sheet'!B29,0) -> 9697.41 | D31: =IFERROR('Data Sheet'!C29,0) -> 6950.7 | E31: =IFERROR('Data Sheet'!D29,0) -> 12548.42 | F31: =IFERROR('Data Sheet'!E29,0) -> 13139.52 | G31: =IFERROR('Data Sheet'!F29,0) -> 20907.65 | H31: =IFERROR('Data Sheet'!G29,0) -> 7506.19 | I31: =IFERROR('Data Sheet'!H29,0) -> 8766.2 | J31: =IFERROR('Data Sheet'!I29,0) -> 4797.04 | ... L31: =IFERROR('Data Sheet'!K29,0) -> 19759.23 | M31: =IFERROR(SUM('Data Sheet'!H29:K29),0) -> 43595.62
B32: Effective Tax Rate | C32: =C31/C28 -> 0.45281991 | D32: =D31/D28 -> 0.36611555 | E32: =E31/E28 -> 0.43280323 | F32: =F31/F28 -> 0.45658037 | G32: =G31/G28 -> 0.46175607 | H32: =H31/H28 -> 0.41745677 | I32: =I31/I28 -> 0.4649039 | J32: =J31/J28 -> 0.10142937 | ... M32: =M31/M28 -> 0.79815754
B34: Net Profit | C34: =C28-C31 -> 11718.19 | D34: =D28-D31 -> 12034.29 | E34: =E28-E31 -> 16444.94 | F34: =F28-F31 -> 15638.59 | G34: =G28-G31 -> 24370.91 | H34: =H28-H31 -> 10474.57 | I34: =I28-I31 -> 10089.74 | J34: =J28-J31 -> 42497.35 | ... M34: =M28-M31 -> 11024.7
B35: Net Margins | C35: =C34/C7 -> 0.072818778 | D35: =D34/D7 -> 0.097022785 | E35: =E34/E7 -> 0.058210918 | F35: =F34/F7 -> 0.048460833 | G35: =G34/G7 -> 0.057802483 | H35: =H34/H7 -> 0.026402403 | I35: =I34/I7 -> 0.033206438 | J35: =J34/J7 -> 0.086509263 | ... M35: =M34/M7 -> 0.016723825
B37: No of Equity Shares | C37: =IFERROR('Data Sheet'!B93,0) -> 1283.32 | D37: =IFERROR('Data Sheet'!C93,0) -> 1283.32 | E37: =IFERROR('Data Sheet'!D93,0) -> 1283.32 | F37: =IFERROR('Data Sheet'!E93,0) -> 1283.32 | G37: =IFERROR('Data Sheet'!F93,0) -> 1258.03 | H37: =IFERROR('Data Sheet'!G93,0) -> 1258.03 | I37: =IFERROR('Data Sheet'!H93,0) -> 1258.03 | J37: =IFERROR('Data Sheet'!I93,0) -> 1258.03 | ... M37: =IFERROR('Data Sheet'!L93,0) -> 0
B39: EPS | C39: =IFERROR(C34/C37,0) -> 9.131152 | D39: =IFERROR(D34/D37,0) -> 9.3774663 | E39: =IFERROR(E34/E37,0) -> 12.814372 | F39: =IFERROR(F34/F37,0) -> 12.186041 | G39: =IFERROR(G34/G37,0) -> 19.37228 | H39: =IFERROR(H34/H37,0) -> 8.3261687 | I39: =IFERROR(I34/I37,0) -> 8.0202698 | J39: =IFERROR(J34/J37,0) -> 33.780872 | ... M39: =IFERROR(M34/M37,0) -> 0
B40: EPS Growth Rate | D40: =D39/C39 -1 -> 0.026975156 | E40: =E39/D39 -1 -> 0.36650687 | F40: =F39/E39 -1 -> -0.04903332 | G40: =G39/F39 -1 -> 0.58971077 | H40: =H39/G39 -1 -> -0.57020193 | I40: =I39/H39 -1 -> -0.036739456 | J40: =J39/I39 -1 -> 3.2119371 | K40: =K39/J39 -1 -> -0.22801257 | ... M40: =M39/L39 -1 -> -1
B42: Dividend per Share | C42: =IFERROR('Data Sheet'!B31/C37,0) -> 6.3333697 | D42: =IFERROR('Data Sheet'!C31/D37,0) -> 5.6667004 | E42: =IFERROR('Data Sheet'!D31/E37,0) -> 7.5500343 | F42: =IFERROR('Data Sheet'!E31/F37,0) -> 6.6000296 | G42: =IFERROR('Data Sheet'!F31/G37,0) -> 7 | H42: =IFERROR('Data Sheet'!G31/H37,0) -> 5 | I42: =IFERROR('Data Sheet'!H31/I37,0) -> 3.5999936 | J42: =IFERROR('Data Sheet'!I31/J37,0) -> 10.49998 | ... M42: =IFERROR('Data Sheet'!L31/M37,0) -> 0
B43: Dividend payout ratio | C43: =C42/C39 -> 0.69360029 | D43: =D42/D39 -> 0.60428908 | E43: =E42/E39 -> 0.58918488 | F43: =F42/F39 -> 0.54160573 | G43: =G42/G39 -> 0.36134104 | H43: =H42/H39 -> 0.6005163 | I43: =I42/I39 -> 0.44886191 | J43: =J42/J39 -> 0.3108262 | ... M43: =M42/M39 -> #DIV/0!
B45: Retained Earnings | C45: =C39-C42 -> 2.7977823 | D45: =D39-D42 -> 3.7107658 | E45: =E39-E42 -> 5.2643378 | F45: =F39-F42 -> 5.5860113 | G45: =G39-G42 -> 12.37228 | H45: =H39-H42 -> 3.3261687 | I45: =I39-I42 -> 4.4202761 | J45: =J39-J42 -> 23.280892 | ... M45: =M39-M42 -> 0
C46: =C45/C39 -> 0.30639971 | D46: =D45/D39 -> 0.39571092 | E46: =E45/E39 -> 0.41081512 | F46: =F45/F39 -> 0.45839427 | G46: =G45/G39 -> 0.63865896 | H46: =H45/H39 -> 0.3994837 | I46: =I45/I39 -> 0.55113809 | J46: =J45/J39 -> 0.6891738 | ... M46: =M45/M39 -> #DIV/0!
A49: # | B49: Balance Sheet
B51: Equity Share Capital | C51: =IFERROR('Data Sheet'!B57,0) -> 4277.76 | D51: =IFERROR('Data Sheet'!C57,0) -> 4277.76 | E51: =IFERROR('Data Sheet'!D57,0) -> 6416.63 | F51: =IFERROR('Data Sheet'!E57,0) -> 6416.63 | G51: =IFERROR('Data Sheet'!F57,0) -> 6290.15 | H51: =IFERROR('Data Sheet'!G57,0) -> 6290.15 | I51: =IFERROR('Data Sheet'!H57,0) -> 6290.14 | J51: =IFERROR('Data Sheet'!I57,0) -> 6290.14 | ... L51: =IFERROR('Data Sheet'!K57,0) -> 6290.14
B52: Reserves | C52: =IFERROR('Data Sheet'!B58,0) -> 176176.64 | D52: =IFERROR('Data Sheet'!C58,0) -> 193535.88 | E52: =IFERROR('Data Sheet'!D58,0) -> 187968.59 | F52: =IFERROR('Data Sheet'!E58,0) -> 197602.3 | G52: =IFERROR('Data Sheet'!F58,0) -> 210644.5 | H52: =IFERROR('Data Sheet'!G58,0) -> 198814.45 | I52: =IFERROR('Data Sheet'!H58,0) -> 214690.85 | J52: =IFERROR('Data Sheet'!I58,0) -> 253212.77 | ... L52: =IFERROR('Data Sheet'!K58,0) -> 330780.09
B53: Borrowings | C53: =IFERROR('Data Sheet'!B59,0) -> 53944.47 | D53: =IFERROR('Data Sheet'!C59,0) -> 45500.17 | E53: =IFERROR('Data Sheet'!D59,0) -> 80029.27 | F53: =IFERROR('Data Sheet'!E59,0) -> 106549.94 | G53: =IFERROR('Data Sheet'!F59,0) -> 107741.69 | H53: =IFERROR('Data Sheet'!G59,0) -> 129472.52 | I53: =IFERROR('Data Sheet'!H59,0) -> 133186.92 | J53: =IFERROR('Data Sheet'!I59,0) -> 121985.86 | ... L53: =IFERROR('Data Sheet'!K59,0) -> 153180.53
B54: Other Liabilities | C54: =IFERROR('Data Sheet'!B60,0) -> 103447.69 | D54: =IFERROR('Data Sheet'!C60,0) -> 98458.57 | E54: =IFERROR('Data Sheet'!D60,0) -> 170110.83 | F54: =IFERROR('Data Sheet'!E60,0) -> 148663.53 | G54: =IFERROR('Data Sheet'!F60,0) -> 167666.95 | H54: =IFERROR('Data Sheet'!G60,0) -> 173786.92 | I54: =IFERROR('Data Sheet'!H60,0) -> 187579.74 | J54: =IFERROR('Data Sheet'!I60,0) -> 201770.75 | ... L54: =IFERROR('Data Sheet'!K60,0) -> 219523.17
B55: Total lIabilities | C55: =IFERROR('Data Sheet'!B61,0) -> 337846.56 | D55: =IFERROR('Data Sheet'!C61,0) -> 341772.38 | E55: =IFERROR('Data Sheet'!D61,0) -> 444525.32 | F55: =IFERROR('Data Sheet'!E61,0) -> 459232.4 | G55: =IFERROR('Data Sheet'!F61,0) -> 492343.29 | H55: =IFERROR('Data Sheet'!G61,0) -> 508364.04 | I55: =IFERROR('Data Sheet'!H61,0) -> 541747.65 | J55: =IFERROR('Data Sheet'!I61,0) -> 583259.52 | ... L55: =IFERROR('Data Sheet'!K61,0) -> 709773.93
B57: Fixed Assets Net Block | C57: =IFERROR('Data Sheet'!B62,0) -> 179932.96 | D57: =IFERROR('Data Sheet'!C62,0) -> 166276.73 | E57: =IFERROR('Data Sheet'!D62,0) -> 211125.43 | F57: =IFERROR('Data Sheet'!E62,0) -> 226057.68 | G57: =IFERROR('Data Sheet'!F62,0) -> 230390.7 | H57: =IFERROR('Data Sheet'!G62,0) -> 243891.96 | I57: =IFERROR('Data Sheet'!H62,0) -> 243746.36 | J57: =IFERROR('Data Sheet'!I62,0) -> 254402.17 | ... L57: =IFERROR('Data Sheet'!K62,0) -> 298454.36
B58: Capital Work in Progress | C58: =IFERROR('Data Sheet'!B63,0) -> 63393.37 | D58: =IFERROR('Data Sheet'!C63,0) -> 57668.48 | E58: =IFERROR('Data Sheet'!D63,0) -> 59042.48 | F58: =IFERROR('Data Sheet'!E63,0) -> 61511.87 | G58: =IFERROR('Data Sheet'!F63,0) -> 69056.44 | H58: =IFERROR('Data Sheet'!G63,0) -> 83832.4 | I58: =IFERROR('Data Sheet'!H63,0) -> 100308.82 | J58: =IFERROR('Data Sheet'!I63,0) -> 106719.23 | ... L58: =IFERROR('Data Sheet'!K63,0) -> 116021.68
B59: Investments | C59: =IFERROR('Data Sheet'!B64,0) -> 4749.14 | D59: =IFERROR('Data Sheet'!C64,0) -> 33386.85 | E59: =IFERROR('Data Sheet'!D64,0) -> 70745.67 | F59: =IFERROR('Data Sheet'!E64,0) -> 67334.61 | G59: =IFERROR('Data Sheet'!F64,0) -> 66908.92 | H59: =IFERROR('Data Sheet'!G64,0) -> 56755.18 | I59: =IFERROR('Data Sheet'!H64,0) -> 60320.36 | J59: =IFERROR('Data Sheet'!I64,0) -> 66642.14 | ... L59: =IFERROR('Data Sheet'!K64,0) -> 102207.2
B60: Other Assets | C60: =IFERROR('Data Sheet'!B65-SUM('Data Sheet'!B67:B69),0) -> 43503.49 | D60: =IFERROR('Data Sheet'!C65-SUM('Data Sheet'!C67:C69),0) -> 40657.6 | E60: =IFERROR('Data Sheet'!D65-SUM('Data Sheet'!D67:D69),0) -> 47296.6 | F60: =IFERROR('Data Sheet'!E65-SUM('Data Sheet'!E67:E69),0) -> 54112.66 | G60: =IFERROR('Data Sheet'!F65-SUM('Data Sheet'!F67:F69),0) -> 69821.7 | H60: =IFERROR('Data Sheet'!G65-SUM('Data Sheet'!G67:G69),0) -> 71005.73 | I60: =IFERROR('Data Sheet'!H65-SUM('Data Sheet'!H67:H69),0) -> 68428.17 | J60: =IFERROR('Data Sheet'!I65-SUM('Data Sheet'!I67:I69),0) -> 74107.49 | ... L60: =IFERROR('Data Sheet'!K65-SUM('Data Sheet'!K67:K69),0) -> 83382.86
...

Sheet Ratio Analysis
B2: ="Ratio Analysis - "&'Profit & Loss'!A1 -> Ratio Analysis - OIL & NATURAL GAS CORPN LTD
B3: Years | C3: =Annual[[#This Row],[Column2]] -> 42094 | D3: =Annual[[#This Row],[Column3]] -> 42460 | E3: =Annual[[#This Row],[Column4]] -> 42825 | F3: =Annual[[#This Row],[Column5]] -> 43190 | G3: =Annual[[#This Row],[Column6]] -> 43555 | H3: =Annual[[#This Row],[Column7]] -> 43921 | I3: =Annual[[#This Row],[Column8]] -> 44286 | J3: =Annual[[#This Row],[Column9]] -> 44651 | K3: =Annual[[#This Row],[Column10]] -> 45016 | L3: =Annual[[#This Row],[Column11]] -> 45382 | M3: Mean | N3: Median | O3: Trend
B5: Sales Growth | D5: =IFERROR('Historical FS'!D8,0) -> -0.22922151 | E5: =IFERROR('Historical FS'!E8,0) -> 1.2776192 | F5: =IFERROR('Historical FS'!F8,0) -> 0.14229657 | G5: =IFERROR('Historical FS'!G8,0) -> 0.30652744 | H5: =IFERROR('Historical FS'!H8,0) -> -0.059047929 | I5: =IFERROR('Historical FS'!I8,0) -> -0.23411259 | J5: =IFERROR('Historical FS'!J8,0) -> 0.61674511 | K5: =IFERROR('Historical FS'!K8,0) -> 0.28711658 | L5: =IFERROR('Historical FS'!L8,0) -> -0.064677353 | M5: =AVERAGE(C5:L5) -> 0.22702728 | N5: =MEDIAN(D5:L5) -> 0.14229657
B6: EBITDA Growth | D6: =IFERROR('Historical FS'!D19/'Historical FS'!C19-1,0) -> -0.075100822 | E6: =IFERROR('Historical FS'!E19/'Historical FS'!D19-1,0) -> 0.34928246 | F6: =IFERROR('Historical FS'!F19/'Historical FS'!E19-1,0) -> 0.077369433 | G6: =IFERROR('Historical FS'!G19/'Historical FS'!F19-1,0) -> 0.3151736 | H6: =IFERROR('Historical FS'!H19/'Historical FS'!G19-1,0) -> -0.30358616 | I6: =IFERROR('Historical FS'!I19/'Historical FS'!H19-1,0) -> -0.050504577 | J6: =IFERROR('Historical FS'!J19/'Historical FS'!I19-1,0) -> 0.61447415 | K6: =IFERROR('Historical FS'!K19/'Historical FS'!J19-1,0) -> -0.054418488 | L6: =IFERROR('Historical FS'!L19/'Historical FS'!K19-1,0) -> 0.36157207 | M6: =AVERAGE(C6:L6) -> 0.13714019 | N6: =MEDIAN(D6:L6) -> 0.077369433
B7: EBIT Growth | D7: =IFERROR('Historical FS'!D28/'Historical FS'!C28-1,0) -> -0.11349717 | E7: =IFERROR('Historical FS'!E28/'Historical FS'!D28-1,0) -> 0.52717278 | F7: =IFERROR('Historical FS'!F28/'Historical FS'!E28-1,0) -> -0.0074241137 | G7: =IFERROR('Historical FS'!G28/'Historical FS'!F28-1,0) -> 0.57336809 | H7: =IFERROR('Historical FS'!H28/'Historical FS'!G28-1,0) -> -0.60288578 | I7: =IFERROR('Historical FS'!I28/'Historical FS'!H28-1,0) -> 0.048673137 | J7: =IFERROR('Historical FS'!J28/'Historical FS'!I28-1,0) -> 1.5081958 | K7: =IFERROR('Historical FS'!K28/'Historical FS'!J28-1,0) -> -0.089097671 | L7: =IFERROR('Historical FS'!L28/'Historical FS'!K28-1,0) -> 0.48276868 | M7: =AVERAGE(C7:L7) -> 0.25858598 | N7: =MEDIAN(D7:L7) -> 0.048673137
B8: Net Profit Growth | D8: =IFERROR('Historical FS'!D34/'Historical FS'!C34-1,0) -> 0.026975156 | E8: =IFERROR('Historical FS'!E34/'Historical FS'!D34-1,0) -> 0.36650687 | F8: =IFERROR('Historical FS'!F34/'Historical FS'!E34-1,0) -> -0.04903332 | G8: =IFERROR('Historical FS'!G34/'Historical FS'!F34-1,0) -> 0.55838282 | H8: =IFERROR('Historical FS'!H34/'Historical FS'!G34-1,0) -> -0.57020193 | I8: =IFERROR('Historical FS'!I34/'Historical FS'!H34-1,0) -> -0.036739456 | J8: =IFERROR('Historical FS'!J34/'Historical FS'!I34-1,0) -> 3.2119371 | K8: =IFERROR('Historical FS'!K34/'Historical FS'!J34-1,0) -> -0.22801257 | L8: =IFERROR('Historical FS'!L34/'Historical FS'!K34-1,0) -> 0.34479609 | M8: =AVERAGE(C8:L8) -> 0.40273453 | N8: =MEDIAN(D8:L8) -> 0.026975156
B9: Dividend Growth | D9: =IFERROR('Historical FS'!D42/'Historical FS'!C42-1,0) -> -0.10526296 | E9: =IFERROR('Historical FS'!E42/'Historical FS'!D42-1,0) -> 0.33235105 | F9: =IFERROR('Historical FS'!F42/'Historical FS'!E42-1,0) -> -0.12582786 | G9: =IFERROR('Historical FS'!G42/'Historical FS'!F42-1,0) -> 0.060601302 | H9: =IFERROR('Historical FS'!H42/'Historical FS'!G42-1,0) -> -0.28571429 | I9: =IFERROR('Historical FS'!I42/'Historical FS'!H42-1,0) -> -0.28000127 | J9: =IFERROR('Historical FS'!J42/'Historical FS'!I42-1,0) -> 1.9166663 | K9: =IFERROR('Historical FS'!K42/'Historical FS'!J42-1,0) -> 0.071429274 | L9: =IFERROR('Historical FS'!L42/'Historical FS'!K42-1,0) -> 0.088888292 | M9: =AVERAGE(C9:L9) -> 0.18590332 | N9: =MEDIAN(D9:L9) -> 0.060601302
B11: Gross Margin | C11: =IFERROR('Historical FS'!C14,0) -> 0.49015813 | D11: =IFERROR('Historical FS'!D14,0) -> 0.54108821 | E11: =IFERROR('Historical FS'!E14,0) -> 0.27811052 | F11: =IFERROR('Historical FS'!F14,0) -> 0.26307228 | G11: =IFERROR('Historical FS'!G14,0) -> 0.26570449 | H11: =IFERROR('Historical FS'!H14,0) -> 0.21941272 | I11: =IFERROR('Historical FS'!I14,0) -> 0.23742317 | J11: =IFERROR('Historical FS'!J14,0) -> 0.23213975 | ... L11: =IFERROR('Historical FS'!L14,0) -> 0.23331463 | M11: =AVERAGE(C11:L11) -> 0.29572155 | N11: =MEDIAN(D11:L11) -> 0.23742317
B12: EBITDA Margin | C12: =IFERROR('Historical FS'!C20,0) -> 0.26293578 | D12: =IFERROR('Historical FS'!D20,0) -> 0.31551099 | E12: =IFERROR('Historical FS'!E20,0) -> 0.1869116 | F12: =IFERROR('Historical FS'!F20,0) -> 0.17628771 | G12: =IFERROR('Historical FS'!G20,0) -> 0.17745433 | H12: =IFERROR('Historical FS'!H20,0) -> 0.13133681 | I12: =IFERROR('Historical FS'!I20,0) -> 0.1628225 | J12: =IFERROR('Historical FS'!J20,0) -> 0.16259379 | ... L12: =IFERROR('Historical FS'!L20,0) -> 0.17388585 | M12: =AVERAGE(C12:L12) -> 0.18691891 | N12: =MEDIAN(D12:L12) -> 0.17388585
B13: EBIT Margin | C13: =IFERROR(('Historical FS'!C19-'Historical FS'!C25)/'Historical FS'!C7,0) -> 0.15087591 | D13: =IFERROR(('Historical FS'!D19-'Historical FS'!D25)/'Historical FS'!D7,0) -> 0.18341952 | E13: =IFERROR(('Historical FS'!E19-'Historical FS'!E25)/'Historical FS'!E7,0) -> 0.11534076 | F13: =IFERROR(('Historical FS'!F19-'Historical FS'!F25)/'Historical FS'!F7,0) -> 0.10466857 | G13: =IFERROR(('Historical FS'!G19-'Historical FS'!G25)/'Historical FS'!G7,0) -> 0.12123432 | H13: =IFERROR(('Historical FS'!H19-'Historical FS'!H25)/'Historical FS'!H7,0) -> 0.064200424 | I13: =IFERROR(('Historical FS'!I19-'Historical FS'!I25)/'Historical FS'!I7,0) -> 0.078772604 | J13: =IFERROR(('Historical FS'!J19-'Historical FS'!J25)/'Historical FS'!J7,0) -> 0.10786939 | ... L13: =IFERROR(('Historical FS'!L19-'Historical FS'!L25)/'Historical FS'!L7,0) -> 0.12525052 | M13: =AVERAGE(C13:L13) -> 0.11322435 | N13: =MEDIAN(D13:L13) -> 0.10786939
B14: EBT Margin | C14: =IFERROR('Historical FS'!C29,0) -> 0.13308009 | D14: =IFERROR('Historical FS'!D29,0) -> 0.15306068 | E14: =IFERROR('Historical FS'!E29,0) -> 0.10262914 | F14: =IFERROR('Historical FS'!F29,0) -> 0.089177553 | G14: =IFERROR('Historical FS'!G29,0) -> 0.10739087 | H14: =IFERROR('Historical FS'!H29,0) -> 0.045322649 | I14: =IFERROR('Historical FS'!I29,0) -> 0.062056961 | J14: =IFERROR('Historical FS'!J29,0) -> 0.096274304 | ... L14: =IFERROR('Historical FS'!L29,0) -> 0.10801306 | M14: =AVERAGE(C14:L14) -> 0.096513938 | N14: =MEDIAN(D14:L14) -> 0.096274304
B15: Net Profit Margin | C15: =IFERROR('Historical FS'!C35,0) -> 0.072818778 | D15: =IFERROR('Historical FS'!D35,0) -> 0.097022785 | E15: =IFERROR('Historical FS'!E35,0) -> 0.058210918 | F15: =IFERROR('Historical FS'!F35,0) -> 0.048460833 | G15: =IFERROR('Historical FS'!G35,0) -> 0.057802483 | H15: =IFERROR('Historical FS'!H35,0) -> 0.026402403 | I15: =IFERROR('Historical FS'!I35,0) -> 0.033206438 | J15: =IFERROR('Historical FS'!J35,0) -> 0.086509263 | ... L15: =IFERROR('Historical FS'!L35,0) -> 0.074601909 | M15: =AVERAGE(C15:L15) -> 0.060692238 | N15: =MEDIAN(D15:L15) -> 0.057802483
B17: Sales Expenses % of Sales | C17: =IFERROR('Historical FS'!C17,0) -> 0.22722235 | D17: =IFERROR('Historical FS'!D17,0) -> 0.22557721 | E17: =IFERROR('Historical FS'!E17,0) -> 0.091198912 | F17: =IFERROR('Historical FS'!F17,0) -> 0.086784568 | G17: =IFERROR('Historical FS'!G17,0) -> 0.088250162 | H17: =IFERROR('Historical FS'!H17,0) -> 0.088075906 | I17: =IFERROR('Historical FS'!I17,0) -> 0.074600663 | J17: =IFERROR('Historical FS'!J17,0) -> 0.069545957 | ... L17: =IFERROR('Historical FS'!L17,0) -> 0.059428783 | M17: =AVERAGE(C17:L17) -> 0.10880265 | N17: =MEDIAN(D17:L17) -> 0.086784568
B18: Depreciation % of Sales | C18: =IFERROR('Historical FS'!C26,0) -> 0.11205987 | D18: =IFERROR('Historical FS'!D26,0) -> 0.13209148 | E18: =IFERROR('Historical FS'!E26,0) -> 0.071570841 | F18: =IFERROR('Historical FS'!F26,0) -> 0.071619143 | G18: =IFERROR('Historical FS'!G26,0) -> 0.056220006 | H18: =IFERROR('Historical FS'!H26,0) -> 0.067136391 | I18: =IFERROR('Historical FS'!I26,0) -> 0.084049898 | J18: =IFERROR('Historical FS'!J26,0) -> 0.054724409 | ... L18: =IFERROR('Historical FS'!L26,0) -> 0.048635326 | M18: =AVERAGE(C18:L18) -> 0.073694557 | N18: =MEDIAN(D18:L18) -> 0.067136391
B19: Operating Income % of Sales | C19: =C13 -> 0.15087591 | D19: =D13 -> 0.18341952 | E19: =E13 -> 0.11534076 | F19: =F13 -> 0.10466857 | G19: =G13 -> 0.12123432 | H19: =H13 -> 0.064200424 | I19: =I13 -> 0.078772604 | J19: =J13 -> 0.10786939 | ... L19: =L13 -> 0.12525052 | M19: =AVERAGE(C19:L19) -> 0.11322435 | N19: =MEDIAN(D19:L19) -> 0.10786939
B21: Return on Capital Employed | C21: =IFERROR(('Historical FS'!C19-'Historical FS'!C25)/(SUM('Historical FS'!C51:C53)),0) -> 0.10358134 | D21: =IFERROR(('Historical FS'!D19-'Historical FS'!D25)/(SUM('Historical FS'!D51:D53)),0) -> 0.093502995 | E21: =IFERROR(('Historical FS'!E19-'Historical FS'!E25)/(SUM('Historical FS'!E51:E53)),0) -> 0.1187418 | F21: =IFERROR(('Historical FS'!F19-'Historical FS'!F25)/(SUM('Historical FS'!F51:F53)),0) -> 0.10875897 | G21: =IFERROR(('Historical FS'!G19-'Historical FS'!G25)/(SUM('Historical FS'!G51:G53)),0) -> 0.1574346 | H21: =IFERROR(('Historical FS'!H19-'Historical FS'!H25)/(SUM('Historical FS'!H51:H53)),0) -> 0.076126246 | I21: =IFERROR(('Historical FS'!I19-'Historical FS'!I25)/(SUM('Historical FS'!I51:I53)),0) -> 0.067580855 | J21: =IFERROR(('Historical FS'!J19-'Historical FS'!J25)/(SUM('Historical FS'!J51:J53)),0) -> 0.1389043 | ... L21: =IFERROR(('Historical FS'!L19-'Historical FS'!L25)/(SUM('Historical FS'!L51:L53)),0) -> 0.15109143 | M21: =AVERAGE(C21:L21) -> 0.11362467 | N21: =MEDIAN(D21:L21) -> 0.1187418
B22: Retained Earnings % | C22: =IFERROR('Historical FS'!C46,0) -> 0.30639971 | D22: =IFERROR('Historical FS'!D46,0) -> 0.39571092 | E22: =IFERROR('Historical FS'!E46,0) -> 0.41081512 | F22: =IFERROR('Historical FS'!F46,0) -> 0.45839427 | G22: =IFERROR('Historical FS'!G46,0) -> 0.63865896 | H22: =IFERROR('Historical FS'!H46,0) -> 0.3994837 | I22: =IFERROR('Historical FS'!I46,0) -> 0.55113809 | J22: =IFERROR('Historical FS'!J46,0) -> 0.6891738 | ... L22: =IFERROR('Historical FS'!L46,0) -> 0.65070063 | M22: =AVERAGE(C22:L22) -> 0.50690844 | N22: =MEDIAN(D22:L22) -> 0.55113809
B23: Return on Equity % | C23: =IFERROR('Historical FS'!C34/SUM('Historical FS'!C51:C52),0) -> 0.064937125 | D23: =IFERROR('Historical FS'!D34/SUM('Historical FS'!D51:D52),0) -> 0.060836502 | E23: =IFERROR('Historical FS'!E34/SUM('Historical FS'!E51:E52),0) -> 0.084599745 | F23: =IFERROR('Historical FS'!F34/SUM('Historical FS'!F51:F52),0) -> 0.076652642 | G23: =IFERROR('Historical FS'!G34/SUM('Historical FS'!G51:G52),0) -> 0.11234217 | H23: =IFERROR('Historical FS'!H34/SUM('Historical FS'!H51:H52),0) -> 0.051069406 | I23: =IFERROR('Historical FS'!I34/SUM('Historical FS'!I51:I52),0) -> 0.04565886 | J23: =IFERROR('Historical FS'!J34/SUM('Historical FS'!J51:J52),0) -> 0.16376444 | ... L23: =IFERROR('Historical FS'!L34/SUM('Historical FS'!L51:L52),0) -> 0.1308905 | M23: =AVERAGE(C23:L23) -> 0.090765051 | N23: =MEDIAN(D23:L23) -> 0.084599745
B24: Self Sustained Growth Rate | C24: =IFERROR(C22*C23,0) -> 0.019896716 | D24: =IFERROR(D22*D23,0) -> 0.024073669 | E24: =IFERROR(E22*E23,0) -> 0.034754854 | F24: =IFERROR(F22*F23,0) -> 0.035137132 | G24: =IFERROR(G22*G23,0) -> 0.071748335 | H24: =IFERROR(H22*H23,0) -> 0.020401395 | I24: =IFERROR(I22*I23,0) -> 0.025164337 | J24: =IFERROR(J22*J23,0) -> 0.11286216 | ... L24: =IFERROR(L22*L23,0) -> 0.08517053 | M24: =AVERAGE(C24:L24) -> 0.049567904 | N24: =MEDIAN(D24:L24) -> 0.035137132
B25: Interest Coverage Ratio | C25: =IFERROR(('Historical FS'!C19-'Historical FS'!C25)/'Historical FS'!C22,0) -> 8.4781667 | D25: =IFERROR(('Historical FS'!D19-'Historical FS'!D25)/'Historical FS'!D22,0) -> 6.0417173 | E25: =IFERROR(('Historical FS'!E19-'Historical FS'!E25)/'Historical FS'!E22,0) -> 9.0736485 | F25: =IFERROR(('Historical FS'!F19-'Historical FS'!F25)/'Historical FS'!F22,0) -> 6.7567273 | G25: =IFERROR(('Historical FS'!G19-'Historical FS'!G25)/'Historical FS'!G22,0) -> 8.7575218 | H25: =IFERROR(('Historical FS'!H19-'Historical FS'!H25)/'Historical FS'!H22,0) -> 3.4008471 | I25: =IFERROR(('Historical FS'!I19-'Historical FS'!I25)/'Historical FS'!I22,0) -> 4.7125081 | J25: =IFERROR(('Historical FS'!J19-'Historical FS'!J25)/'Historical FS'!J22,0) -> 9.3030298 | ... L25: =IFERROR(('Historical FS'!L19-'Historical FS'!L25)/'Historical FS'!L22,0) -> 7.2661816 | M25: =AVERAGE(C25:L25) -> 7.0250939 | N25: =MEDIAN(D25:L25) -> 6.7567273
B27: Debtor Turnover Ratio | C27: =IFERROR('Historical FS'!C7/'Historical FS'!C63,0) -> 8.552518 | D27: =IFERROR('Historical FS'!D7/'Historical FS'!D63,0) -> 14.887185 | E27: =IFERROR('Historical FS'!E7/'Historical FS'!E63,0) -> 22.515614 | F27: =IFERROR('Historical FS'!F7/'Historical FS'!F63,0) -> 23.217628 | G27: =IFERROR('Historical FS'!G7/'Historical FS'!G63,0) -> 27.384472 | H27: =IFERROR('Historical FS'!H7/'Historical FS'!H63,0) -> 43.247594 | I27: =IFERROR('Historical FS'!I7/'Historical FS'!I63,0) -> 18.971787 | J27: =IFERROR('Historical FS'!J7/'Historical FS'!J63,0) -> 25.602703 | ... L27: =IFERROR('Historical FS'!L7/'Historical FS'!L63,0) -> 29.924493 | M27: =AVERAGE(C27:L27) -> 24.802335 | N27: =MEDIAN(D27:L27) -> 25.602703
B28: Creditor Turnver Ratio | C28: =IFERROR('Historical FS'!C7/'Historical FS'!C54,0) -> 1.5555943 | D28: =IFERROR('Historical FS'!D7/'Historical FS'!D54,0) -> 1.2597757 | E28: =IFERROR('Historical FS'!E7/'Historical FS'!E54,0) -> 1.660718 | F28: =IFERROR('Historical FS'!F7/'Historical FS'!F54,0) -> 2.1707123 | G28: =IFERROR('Historical FS'!G7/'Historical FS'!G54,0) -> 2.5146514 | H28: =IFERROR('Historical FS'!H7/'Historical FS'!H54,0) -> 2.282841 | I28: =IFERROR('Historical FS'!I7/'Historical FS'!I54,0) -> 1.6198386 | J28: =IFERROR('Historical FS'!J7/'Historical FS'!J54,0) -> 2.4346752 | ... L28: =IFERROR('Historical FS'!L7/'Historical FS'!L54,0) -> 2.6940038 | M28: =AVERAGE(C28:L28) -> 2.1516942 | N28: =MEDIAN(D28:L28) -> 2.282841
B29: Inventory Turnover | C29: =IFERROR('Historical FS'!C7/'Historical FS'!C64,0) -> 14.172138 | D29: =IFERROR('Historical FS'!D7/'Historical FS'!D64,0) -> 11.525372 | E29: =IFERROR('Historical FS'!E7/'Historical FS'!E64,0) -> 9.2457076 | F29: =IFERROR('Historical FS'!F7/'Historical FS'!F64,0) -> 10.325405 | G29: =IFERROR('Historical FS'!G7/'Historical FS'!G64,0) -> 11.728257 | H29: =IFERROR('Historical FS'!H7/'Historical FS'!H64,0) -> 11.646162 | I29: =IFERROR('Historical FS'!I7/'Historical FS'!I64,0) -> 6.643561 | J29: =IFERROR('Historical FS'!J7/'Historical FS'!J64,0) -> 8.8736244 | ... L29: =IFERROR('Historical FS'!L7/'Historical FS'!L64,0) -> 11.10494 | M29: =AVERAGE(C29:L29) -> 10.924202 | N29: =MEDIAN(D29:L29) -> 11.10494
B30: Fixed Asset Turnover | C30: =IFERROR('Historical FS'!C7/'Historical FS'!C57,0) -> 0.89434776 | D30: =IFERROR('Historical FS'!D7/'Historical FS'!D57,0) -> 0.74595952 | E30: =IFERROR('Historical FS'!E7/'Historical FS'!E57,0) -> 1.3380961 | F30: =IFERROR('Historical FS'!F7/'Historical FS'!F57,0) -> 1.4275373 | G30: =IFERROR('Historical FS'!G7/'Historical FS'!G57,0) -> 1.8300388 | H30: =IFERROR('Historical FS'!H7/'Historical FS'!H57,0) -> 1.6266543 | I30: =IFERROR('Historical FS'!I7/'Historical FS'!I57,0) -> 1.2465782 | J30: =IFERROR('Historical FS'!J7/'Historical FS'!J57,0) -> 1.9309829 | ... L30: =IFERROR('Historical FS'!L7/'Historical FS'!L57,0) -> 1.98153 | M30: =AVERAGE(C30:L30) -> 1.5542627 | N30: =MEDIAN(D30:L30) -> 1.6266543
B31: Capital Turnover Ratio | C31: =IFERROR('Historical FS'!C7/SUM('Historical FS'!C51:C52),0) -> 0.89176346 | D31: =IFERROR('Historical FS'!D7/SUM('Historical FS'!D51:D52),0) -> 0.62703315 | E31: =IFERROR('Historical FS'!E7/SUM('Historical FS'!E51:E52),0) -> 1.4533312 | F31: =IFERROR('Historical FS'!F7/SUM('Historical FS'!F51:F52),0) -> 1.5817442 | G31: =IFERROR('Historical FS'!G7/SUM('Historical FS'!G51:G52),0) -> 1.9435527 | H31: =IFERROR('Historical FS'!H7/SUM('Historical FS'!H51:H52),0) -> 1.9342711 | I31: =IFERROR('Historical FS'!I7/SUM('Historical FS'!I51:I52),0) -> 1.3750002 | J31: =IFERROR('Historical FS'!J7/SUM('Historical FS'!J51:J52),0) -> 1.8930279 | ... L31: =IFERROR('Historical FS'!L7/SUM('Historical FS'!L51:L52),0) -> 1.7545194 | M31: =AVERAGE(C31:L31) -> 1.5707218 | N31: =MEDIAN(D31:L31) -> 1.7545194
B33: Debtor Days | C33: =IFERROR(365/C27,0) -> 42.67749 | D33: =IFERROR(365/D27,0) -> 24.517731 | E33: =IFERROR(365/E27,0) -> 16.210973 | F33: =IFERROR(365/F27,0) -> 15.720813 | G33: =IFERROR(365/G27,0) -> 13.328721 | H33: =IFERROR(365/H27,0) -> 8.4397759 | I33: =IFERROR(365/I27,0) -> 19.239095 | J33: =IFERROR(365/J27,0) -> 14.256307 | ... L33: =IFERROR(365/L27,0) -> 12.197366 | M33: =AVERAGE(C33:L33) -> 17.741292 | N33: =MEDIAN(D33:L33) -> 14.256307
B34: Payable Days | C34: =IFERROR(365/C28,0) -> 234.63701 | D34: =IFERROR(365/D28,0) -> 289.73413 | E34: =IFERROR(365/E28,0) -> 219.78446 | F34: =IFERROR(365/F28,0) -> 168.14757 | G34: =IFERROR(365/G28,0) -> 145.14934 | H34: =IFERROR(365/H28,0) -> 159.88849 | I34: =IFERROR(365/I28,0) -> 225.33109 | J34: =IFERROR(365/J28,0) -> 149.91733 | ... L34: =IFERROR(365/L28,0) -> 135.48607 | M34: =AVERAGE(C34:L34) -> 183.78786 | N34: =MEDIAN(D34:L34) -> 159.88849
B35: Inventory Days | C35: =IFERROR(365/C29,0) -> 25.75476 | D35: =IFERROR(365/D29,0) -> 31.669259 | E35: =IFERROR(365/E29,0) -> 39.477779 | F35: =IFERROR(365/F29,0) -> 35.349704 | G35: =IFERROR(365/G29,0) -> 31.121418 | H35: =IFERROR(365/H29,0) -> 31.340797 | I35: =IFERROR(365/I29,0) -> 54.940415 | J35: =IFERROR(365/J29,0) -> 41.133136 | ... L35: =IFERROR(365/L29,0) -> 32.868254 | M35: =AVERAGE(C35:L35) -> 34.977013 | N35: =MEDIAN(D35:L35) -> 32.868254
B36: Cash Conversion Cycle (in days) | C36: =IFERROR(SUM(C33+C35)-C34,0) -> -166.20476 | D36: =IFERROR(SUM(D33+D35)-D34,0) -> -233.54714 | E36: =IFERROR(SUM(E33+E35)-E34,0) -> -164.09571 | F36: =IFERROR(SUM(F33+F35)-F34,0) -> -117.07705 | G36: =IFERROR(SUM(G33+G35)-G34,0) -> -100.6992 | H36: =IFERROR(SUM(H33+H35)-H34,0) -> -120.10792 | I36: =IFERROR(SUM(I33+I35)-I34,0) -> -151.15158 | J36: =IFERROR(SUM(J33+J35)-J34,0) -> -94.527885 | ... N36: =IFERROR(SUM(N33+N35)-N34,0) -> -112.76393
B38: CFO/Sales | C38: =IFERROR('Historical FS'!C84/'Historical FS'!C7,0) -> 0.13867533 | D38: =IFERROR('Historical FS'!D84/'Historical FS'!D7,0) -> 0.43115809 | E38: =IFERROR('Historical FS'!E84/'Historical FS'!E7,0) -> 0.15258785 | F38: =IFERROR('Historical FS'!F84/'Historical FS'!F7,0) -> 0.17676784 | G38: =IFERROR('Historical FS'!G84/'Historical FS'!G7,0) -> 0.12247644 | H38: =IFERROR('Historical FS'!H84/'Historical FS'!H7,0) -> 0.20995498 | I38: =IFERROR('Historical FS'!I84/'Historical FS'!I7,0) -> 0.14232073 | J38: =IFERROR('Historical FS'!J84/'Historical FS'!J7,0) -> 0.16684911 | ... L38: =IFERROR('Historical FS'!L84/'Historical FS'!L7,0) -> 0.16807343 | M38: =AVERAGE(C38:L38) -> 0.18587473 | N38: =MEDIAN(D38:L38) -> 0.16684911
B39: CFO/Total Assets | C39: =IFERROR('Historical FS'!C84/'Historical FS'!C68,0) -> 0.066053655 | D39: =IFERROR('Historical FS'!D84/'Historical FS'!D68,0) -> 0.15647549 | E39: =IFERROR('Historical FS'!E84/'Historical FS'!E68,0) -> 0.096973104 | F39: =IFERROR('Historical FS'!F84/'Historical FS'!F68,0) -> 0.12421597 | G39: =IFERROR('Historical FS'!G84/'Historical FS'!G68,0) -> 0.10488413 | H39: =IFERROR('Historical FS'!H84/'Historical FS'!H68,0) -> 0.16384912 | I39: =IFERROR('Historical FS'!I84/'Historical FS'!I68,0) -> 0.079823143 | J39: =IFERROR('Historical FS'!J84/'Historical FS'!J68,0) -> 0.1405275 | ... L39: =IFERROR('Historical FS'!L84/'Historical FS'!L68,0) -> 0.14004177 | M39: =AVERAGE(C39:L39) -> 0.12274153 | N39: =MEDIAN(D39:L39) -> 0.14004177
